<robot name="robot_model" version="1.0">
  <joint name="arm_1_link_joint" type="continuous">
    <limit lower="0" upper="0" effort="0.00000" velocity="0.00000"/>
    <origin rpy="0.00000 0.00000 0.00000" xyz="-0.00000 0.00000 0.65000"/>
    <parent link="arm_column_link"/>
    <child link="arm_1_link"/>
    <axis xyz="0.00000 0.00000 1.00000"/>
  </joint>
  <joint name="arm_2_link_joint" type="continuous">
    <limit lower="0" upper="0" effort="0.00000" velocity="0.00000"/>
    <origin rpy="0.00000 0.00000 0.00000" xyz="0.00000 -1.00000 0.20000"/>
    <parent link="arm_1_link"/>
    <child link="arm_2_link"/>
    <axis xyz="0.00000 0.00000 1.00000"/>
  </joint>
  <joint name="arm_base_link_joint" type="fixed">
    <origin rpy="0.00000 0.00000 0.00000" xyz="0.00000 -1.08925 0.52413"/>
    <parent link="chasis_link"/>
    <child link="arm_base_link"/>
  </joint>
  <joint name="arm_column_link_joint" type="continuous">
    <limit lower="0" upper="0" effort="0.00000" velocity="0.00000"/>
    <origin rpy="0.00000 0.00000 0.00000" xyz="0.00000 0.00000 0.85000"/>
    <parent link="arm_base_link"/>
    <child link="arm_column_link"/>
    <axis xyz="0.00000 0.00000 1.00000"/>
  </joint>
  <joint name="arm_gripper_link_joint" type="prismatic">
    <limit lower="-0.20000" upper="-1.80000" effort="0.00000" velocity="0.00000"/>
    <origin rpy="0.00000 0.00000 0.00000" xyz="-0.00000 -1.00000 -0.07053"/>
    <parent link="arm_2_link"/>
    <child link="arm_gripper_link"/>
    <axis xyz="0.00000 0.00000 1.00000"/>
  </joint>
  <joint name="box_down_side_link_joint" type="fixed">
    <origin rpy="0.00000 0.00000 1.57080" xyz="0.00000 1.86075 0.77413"/>
    <parent link="chasis_link"/>
    <child link="box_down_side_link"/>
  </joint>
  <joint name="box_left_side_link_joint" type="fixed">
    <origin rpy="0.00000 0.00000 0.00000" xyz="0.45000 0.91075 0.77413"/>
    <parent link="chasis_link"/>
    <child link="box_left_side_link"/>
  </joint>
  <joint name="box_right_side_link_joint" type="fixed">
    <origin rpy="0.00000 0.00000 0.00000" xyz="-0.45000 0.91075 0.77413"/>
    <parent link="chasis_link"/>
    <child link="box_right_side_link"/>
  </joint>
  <joint name="box_up_side_link_joint" type="fixed">
    <origin rpy="0.00000 0.00000 1.57080" xyz="0.00000 -0.03925 0.77413"/>
    <parent link="chasis_link"/>
    <child link="box_up_side_link"/>
  </joint>
  <joint name="gripper_left_link_joint" type="prismatic">
    <limit lower="0.00000" upper="-0.25000" effort="0.00000" velocity="0.00000"/>
    <origin rpy="0.00000 -1.57080 0.00000" xyz="0.32000 -0.00000 -2.53589"/>
    <parent link="arm_gripper_link"/>
    <child link="gripper_left_link"/>
    <axis xyz="0.00000 0.00000 1.00000"/>
  </joint>
  <joint name="gripper_right_link_joint" type="prismatic">
    <limit lower="0.00000" upper="0.25000" effort="0.00000" velocity="0.00000"/>
    <origin rpy="-0.00000 1.57080 0.00000" xyz="-0.32000 -0.00000 -2.53589"/>
    <parent link="arm_gripper_link"/>
    <child link="gripper_right_link"/>
    <axis xyz="0.00000 0.00000 1.00000"/>
  </joint>
  <joint name="subjection_down_left_wheel_link_joint" type="fixed">
    <origin rpy="0.00000 0.00000 0.00000" xyz="0.53571 0.91075 -0.81158"/>
    <parent link="chasis_link"/>
    <child link="subjection_down_left_wheel_link"/>
  </joint>
  <joint name="subjection_down_right_wheel_link_joint" type="fixed">
    <origin rpy="0.00000 0.00000 0.00000" xyz="-0.53571 0.91075 -0.81158"/>
    <parent link="chasis_link"/>
    <child link="subjection_down_right_wheel_link"/>
  </joint>
  <joint name="subjection_up_left_wheel_link_joint" type="fixed">
    <origin rpy="0.00000 0.00000 0.00000" xyz="0.53571 -1.08925 -0.81158"/>
    <parent link="chasis_link"/>
    <child link="subjection_up_left_wheel_link"/>
  </joint>
  <joint name="subjection_up_right_wheel_link_joint" type="fixed">
    <origin rpy="0.00000 0.00000 0.00000" xyz="-0.53571 -1.08925 -0.81158"/>
    <parent link="chasis_link"/>
    <child link="subjection_up_right_wheel_link"/>
  </joint>
  <joint name="wheel_down_left_link_joint" type="continuous">
    <limit lower="0" upper="0" effort="0.00000" velocity="0.00000"/>
    <origin rpy="-0.00000 1.57080 0.00000" xyz="0.26429 0.00000 -0.06429"/>
    <parent link="subjection_down_left_wheel_link"/>
    <child link="wheel_down_left_link"/>
    <axis xyz="0.00000 0.00000 1.00000"/>
  </joint>
  <joint name="wheel_down_right_link_joint" type="continuous">
    <limit lower="0" upper="0" effort="0.00000" velocity="0.00000"/>
    <origin rpy="-0.00000 1.57080 0.00000" xyz="-0.26429 0.00000 -0.06429"/>
    <parent link="subjection_down_right_wheel_link"/>
    <child link="wheel_down_right_link"/>
    <axis xyz="0.00000 0.00000 1.00000"/>
  </joint>
  <joint name="wheel_up_left_link_joint" type="continuous">
    <limit lower="0" upper="0" effort="0.00000" velocity="0.00000"/>
    <origin rpy="-0.00000 1.57080 0.00000" xyz="0.26429 0.00000 -0.06429"/>
    <parent link="subjection_up_left_wheel_link"/>
    <child link="wheel_up_left_link"/>
    <axis xyz="0.00000 0.00000 1.00000"/>
  </joint>
  <joint name="wheel_up_right_link_joint" type="continuous">
    <limit lower="0" upper="0" effort="0.00000" velocity="0.00000"/>
    <origin rpy="-0.00000 1.57080 0.00000" xyz="-0.26429 0.00000 -0.06429"/>
    <parent link="subjection_up_right_wheel_link"/>
    <child link="wheel_up_right_link"/>
    <axis xyz="0.00000 0.00000 1.00000"/>
  </joint>
  <link name="arm_1_link">
    <collision name="arm_1_collision">
      <origin rpy="0.00000 0.00000 0.00000" xyz="0.00000 -0.50000 0.00000"/>
      <geometry>
        <mesh filename="../meshes/dae/Cylinder.015.dae" scale="0.20000 0.20000 0.10000"/>
      </geometry>
    </collision>
    <inertial>
      <inertia ixx="0.70318" ixy="-0.00000" ixz="0.00000" iyy="0.07043" iyz="0.00000" izz="0.74238"/>
      <origin rpy="0.00000 0.00000 0.00000" xyz="0.00000 -0.50000 0.00000"/>
      <mass value="5.00000"/>
    </inertial>
    <visual name="arm_1">
      <origin rpy="0.00000 0.00000 0.00000" xyz="0.00000 -0.50000 0.00000"/>
      <material name="yellow.001"/>
      <geometry>
        <mesh filename="../meshes/dae/Cylinder.015.dae" scale="0.20000 0.20000 0.10000"/>
      </geometry>
    </visual>
  </link>
  <link name="arm_2_link">
    <collision name="arm_2_collision">
      <origin rpy="0.00000 0.00000 0.00000" xyz="0.00000 -0.50000 0.00000"/>
      <geometry>
        <mesh filename="../meshes/dae/Cylinder.017.dae" scale="0.20000 0.20000 0.10000"/>
      </geometry>
    </collision>
    <inertial>
      <inertia ixx="0.70318" ixy="-0.00000" ixz="0.00000" iyy="0.07043" iyz="0.00000" izz="0.74238"/>
      <origin rpy="0.00000 0.00000 0.00000" xyz="0.00000 -0.50000 0.00000"/>
      <mass value="5.00000"/>
    </inertial>
    <visual name="arm_2">
      <origin rpy="0.00000 0.00000 0.00000" xyz="0.00000 -0.50000 0.00000"/>
      <material name="yellow.001"/>
      <geometry>
        <mesh filename="../meshes/dae/Cylinder.017.dae" scale="0.20000 0.20000 0.10000"/>
      </geometry>
    </visual>
  </link>
  <link name="arm_base_link">
    <collision name="arm_base_collision">
      <origin rpy="0.00000 0.00000 0.00000" xyz="0.00000 0.00000 0.00000"/>
      <geometry>
        <cylinder radius="0.30000" length="0.20000"/>
      </geometry>
    </collision>
    <inertial>
      <inertia ixx="0.12917" ixy="0.00000" ixz="0.00000" iyy="0.12917" iyz="0.00000" izz="0.22500"/>
      <origin rpy="0.00000 0.00000 0.00000" xyz="0.00000 0.00000 0.00000"/>
      <mass value="5.00000"/>
    </inertial>
    <visual name="arm_base">
      <origin rpy="0.00000 0.00000 0.00000" xyz="0.00000 0.00000 0.00000"/>
      <material name="yellow.001"/>
      <geometry>
        <cylinder radius="0.30000" length="0.20000"/>
      </geometry>
    </visual>
  </link>
  <link name="arm_column_link">
    <collision name="arm_column_collision">
      <origin rpy="0.00000 0.00000 0.00000" xyz="0.00000 0.00000 0.00000"/>
      <geometry>
        <cylinder radius="0.15000" length="1.50000"/>
      </geometry>
    </collision>
    <inertial>
      <inertia ixx="1.93125" ixy="0.00000" ixz="0.00000" iyy="1.93125" iyz="0.00000" izz="0.11250"/>
      <origin rpy="0.00000 0.00000 0.00000" xyz="0.00000 0.00000 0.00000"/>
      <mass value="10.00000"/>
    </inertial>
    <visual name="arm_column">
      <origin rpy="0.00000 0.00000 0.00000" xyz="0.00000 0.00000 0.00000"/>
      <material name="yellow.001"/>
      <geometry>
        <cylinder radius="0.15000" length="1.50000"/>
      </geometry>
    </visual>
  </link>
  <link name="arm_gripper_link">
    <collision name="arm_gripper_collision">
      <origin rpy="0.00000 0.00000 0.00000" xyz="0.00000 -0.00000 0.00003"/>
      <geometry>
        <mesh filename="../meshes/dae/Cube.007.dae" scale="0.35000 0.15000 0.02500"/>
      </geometry>
    </collision>
    <inertial>
      <inertia ixx="6.42247" ixy="0.00000" ixz="-0.00000" iyy="6.52276" iyz="0.00000" izz="0.20346"/>
      <origin rpy="0.00000 0.00000 0.00000" xyz="0.00000 -0.00000 1.05646"/>
      <mass value="10.00000"/>
    </inertial>
    <visual name="arm_gripper">
      <origin rpy="0.00000 0.00000 0.00000" xyz="0.00000 -0.00000 0.00000"/>
      <material name="yellow.001"/>
      <geometry>
        <mesh filename="../meshes/dae/Cube.007.dae" scale="0.35000 0.15000 0.02500"/>
      </geometry>
    </visual>
  </link>
  <link name="box_down_side_link">
    <collision name="box_down_side_collision">
      <origin rpy="0.00000 0.00000 0.00000" xyz="0.00000 0.00000 0.00000"/>
      <geometry>
        <box size="0.10000 0.80000 0.70000"/>
      </geometry>
    </collision>
    <inertial>
      <inertia ixx="0.41667" ixy="-0.00000" ixz="0.00000" iyy="0.94167" iyz="0.00000" izz="0.54167"/>
      <origin rpy="0.00000 0.00000 0.00000" xyz="0.00000 0.00000 0.00000"/>
      <mass value="10.00000"/>
    </inertial>
    <visual name="box_down_side">
      <origin rpy="0.00000 0.00000 0.00000" xyz="0.00000 0.00000 0.00000"/>
      <material name="red.001"/>
      <geometry>
        <box size="0.10000 0.80000 0.70000"/>
      </geometry>
    </visual>
  </link>
  <link name="box_left_side_link">
    <collision name="box_left_side_collision">
      <origin rpy="0.00000 0.00000 0.00000" xyz="-0.00000 -0.00000 -0.00000"/>
      <geometry>
        <box size="0.10000 2.00000 0.70000"/>
      </geometry>
    </collision>
    <inertial>
      <inertia ixx="3.74167" ixy="0.00000" ixz="0.00000" iyy="0.41667" iyz="0.00000" izz="3.34167"/>
      <origin rpy="0.00000 0.00000 0.00000" xyz="-0.00000 -0.00000 -0.00000"/>
      <mass value="10.00000"/>
    </inertial>
    <visual name="box_left_side">
      <origin rpy="0.00000 0.00000 0.00000" xyz="-0.00000 0.00000 -0.00000"/>
      <material name="red.001"/>
      <geometry>
        <box size="0.10000 2.00000 0.70000"/>
      </geometry>
    </visual>
  </link>
  <link name="box_right_side_link">
    <collision name="box_right_side_collision">
      <origin rpy="0.00000 0.00000 0.00000" xyz="0.00000 -0.00000 -0.00000"/>
      <geometry>
        <box size="0.10000 2.00000 0.70000"/>
      </geometry>
    </collision>
    <inertial>
      <inertia ixx="3.74167" ixy="0.00000" ixz="0.00000" iyy="0.41667" iyz="0.00000" izz="3.34167"/>
      <origin rpy="0.00000 0.00000 0.00000" xyz="0.00000 -0.00000 -0.00000"/>
      <mass value="10.00000"/>
    </inertial>
    <visual name="box_right_side">
      <origin rpy="0.00000 0.00000 0.00000" xyz="0.00000 0.00000 -0.00000"/>
      <material name="red.001"/>
      <geometry>
        <box size="0.10000 2.00000 0.70000"/>
      </geometry>
    </visual>
  </link>
  <link name="box_up_side_link">
    <collision name="box_up_side_collision">
      <origin rpy="0.00000 0.00000 0.00000" xyz="-0.00000 0.00000 -0.00000"/>
      <geometry>
        <box size="0.10000 0.80000 0.70000"/>
      </geometry>
    </collision>
    <inertial>
      <inertia ixx="0.41667" ixy="-0.00000" ixz="0.00000" iyy="0.94167" iyz="0.00000" izz="0.54167"/>
      <origin rpy="0.00000 0.00000 0.00000" xyz="-0.00000 0.00000 -0.00000"/>
      <mass value="10.00000"/>
    </inertial>
    <visual name="box_up_side">
      <origin rpy="0.00000 0.00000 -0.00000" xyz="-0.00000 -0.00000 -0.00000"/>
      <material name="red.001"/>
      <geometry>
        <box size="0.10000 0.80000 0.70000"/>
      </geometry>
    </visual>
  </link>
  <link name="chasis_link">
    <collision name="chasis_collision">
      <origin rpy="0.00000 0.00000 0.00000" xyz="0.00000 -0.09000 -0.07000"/>
      <geometry>
        <box size="1.00000 4.00000 1.00000"/>
      </geometry>
    </collision>
    <inertial>
      <inertia ixx="182.69966" ixy="-0.00000" ixz="0.00000" iyy="44.38927" iyz="-36.14004" izz="154.63375"/>
      <origin rpy="0.00000 0.00000 0.00000" xyz="0.00000 0.29214 0.24832"/>
      <mass value="100.00000"/>
    </inertial>
    <visual name="chasis">
      <origin rpy="0.00000 0.00000 0.00000" xyz="0.00000 -0.00000 -0.00000"/>
      <material name="red.001"/>
      <geometry>
        <mesh filename="../meshes/dae/Cube.003.dae" scale="0.05000 1.00000 0.35000"/>
      </geometry>
    </visual>
  </link>
  <link name="gripper_left_link">
    <collision name="gripper_left_collision">
      <origin rpy="3.14159 -0.00000 3.14159" xyz="1.05643 0.00000 -0.00000"/>
      <geometry>
        <mesh filename="../meshes/dae/Cube.009.dae" scale="0.30000 0.15000 0.02500"/>
      </geometry>
    </collision>
    <inertial>
      <inertia ixx="0.18750" ixy="0.00000" ixz="0.00000" iyy="0.15104" iyz="0.00000" izz="0.03854"/>
      <origin rpy="0.00000 0.00000 0.00000" xyz="1.05643 0.00000 -0.00000"/>
      <mass value="5.00000"/>
    </inertial>
    <visual name="gripper_left">
      <origin rpy="3.14159 0.00000 3.14159" xyz="1.05643 0.00000 -0.00000"/>
      <material name="yellow.001"/>
      <geometry>
        <mesh filename="../meshes/dae/Cube.009.dae" scale="0.30000 0.15000 0.02500"/>
      </geometry>
    </visual>
  </link>
  <link name="gripper_right_link">
    <collision name="gripper_right_collision">
      <origin rpy="0.00000 0.00000 0.00000" xyz="-1.05643 0.00000 0.00000"/>
      <geometry>
        <mesh filename="../meshes/dae/Cube.008.dae" scale="0.30000 0.15000 0.02500"/>
      </geometry>
    </collision>
    <inertial>
      <inertia ixx="0.18750" ixy="0.00000" ixz="-0.00000" iyy="0.15104" iyz="0.00000" izz="0.03854"/>
      <origin rpy="0.00000 0.00000 0.00000" xyz="-1.05643 0.00000 0.00000"/>
      <mass value="5.00000"/>
    </inertial>
    <visual name="gripper_right">
      <origin rpy="0.00000 -0.00000 0.00000" xyz="-1.05643 0.00000 0.00000"/>
      <material name="yellow.001"/>
      <geometry>
        <mesh filename="../meshes/dae/Cube.008.dae" scale="0.30000 0.15000 0.02500"/>
      </geometry>
    </visual>
  </link>
  <link name="subjection_down_left_wheel_link">
    <collision name="subjection_down_left_wheel_collision">
      <origin rpy="-0.00000 1.57080 0.00000" xyz="-0.00000 0.00000 0.00000"/>
      <geometry>
        <mesh filename="../meshes/dae/Cylinder.009.dae" scale="0.05000 0.05000 0.20000"/>
      </geometry>
    </collision>
    <inertial>
      <inertia ixx="0.09178" ixy="0.00000" ixz="0.05238" iyy="0.21726" iyz="-0.00000" izz="0.13657"/>
      <origin rpy="0.00000 0.00000 0.00000" xyz="0.00000 0.00000 0.00000"/>
      <mass value="10.00000"/>
    </inertial>
    <visual name="subjection_down_left_wheel">
      <origin rpy="-0.00000 1.57080 0.00000" xyz="0.00000 0.00000 0.00000"/>
      <material name="black.007"/>
      <geometry>
        <mesh filename="../meshes/dae/Cylinder.009.dae" scale="0.05000 0.05000 0.20000"/>
      </geometry>
    </visual>
  </link>
  <link name="subjection_down_right_wheel_link">
    <collision name="subjection_down_right_wheel_collision">
      <origin rpy="-0.00000 1.57080 0.00000" xyz="0.00000 0.00000 0.00000"/>
      <geometry>
        <mesh filename="../meshes/dae/Cylinder.004.dae" scale="0.05000 0.05000 0.20000"/>
      </geometry>
    </collision>
    <inertial>
      <inertia ixx="0.09178" ixy="-0.00000" ixz="-0.05238" iyy="0.21726" iyz="-0.00000" izz="0.13657"/>
      <origin rpy="0.00000 0.00000 0.00000" xyz="-0.00000 0.00000 0.00000"/>
      <mass value="10.00000"/>
    </inertial>
    <visual name="subjection_down_right_wheel">
      <origin rpy="-0.00000 1.57080 0.00000" xyz="0.00000 0.00000 0.00000"/>
      <material name="black.007"/>
      <geometry>
        <mesh filename="../meshes/dae/Cylinder.004.dae" scale="0.05000 0.05000 0.20000"/>
      </geometry>
    </visual>
  </link>
  <link name="subjection_up_left_wheel_link">
    <collision name="subjection_up_left_wheel_collision">
      <origin rpy="-0.00000 1.57080 0.00000" xyz="-0.00000 0.00000 0.00000"/>
      <geometry>
        <mesh filename="../meshes/dae/Cylinder.010.dae" scale="0.05000 0.05000 0.20000"/>
      </geometry>
    </collision>
    <inertial>
      <inertia ixx="0.09178" ixy="0.00000" ixz="0.05238" iyy="0.21726" iyz="-0.00000" izz="0.13657"/>
      <origin rpy="0.00000 0.00000 0.00000" xyz="0.00000 0.00000 0.00000"/>
      <mass value="10.00000"/>
    </inertial>
    <visual name="subjection_up_left_wheel">
      <origin rpy="-0.00000 1.57080 0.00000" xyz="0.00000 0.00000 0.00000"/>
      <material name="black.007"/>
      <geometry>
        <mesh filename="../meshes/dae/Cylinder.010.dae" scale="0.05000 0.05000 0.20000"/>
      </geometry>
    </visual>
  </link>
  <link name="subjection_up_right_wheel_link">
    <collision name="subjection_up_right_wheel_collision">
      <origin rpy="-0.00000 1.57080 0.00000" xyz="0.00000 0.00000 0.00000"/>
      <geometry>
        <mesh filename="../meshes/dae/Cylinder.011.dae" scale="0.05000 0.05000 0.20000"/>
      </geometry>
    </collision>
    <inertial>
      <inertia ixx="0.09178" ixy="-0.00000" ixz="-0.05238" iyy="0.21726" iyz="-0.00000" izz="0.13657"/>
      <origin rpy="0.00000 0.00000 0.00000" xyz="-0.00000 0.00000 0.00000"/>
      <mass value="10.00000"/>
    </inertial>
    <visual name="subjection_up_right_wheel">
      <origin rpy="-0.00000 1.57080 0.00000" xyz="0.00000 0.00000 0.00000"/>
      <material name="black.007"/>
      <geometry>
        <mesh filename="../meshes/dae/Cylinder.011.dae" scale="0.05000 0.05000 0.20000"/>
      </geometry>
    </visual>
  </link>
  <link name="wheel_down_left_link">
    <collision name="wheel_down_left_collision">
      <origin rpy="0.00000 -1.57080 0.00000" xyz="-0.00000 0.00000 0.00000"/>
      <geometry>
        <mesh filename="../meshes/dae/Cylinder.002.dae" scale="0.05000 0.05000 0.20000"/>
      </geometry>
    </collision>
    <inertial>
      <inertia ixx="0.28017" ixy="0.00000" ixz="-0.00000" iyy="0.16408" iyz="-0.00000" izz="0.15377"/>
      <origin rpy="0.00000 0.00000 0.00000" xyz="-0.00000 0.00000 0.00000"/>
      <mass value="10.00000"/>
    </inertial>
    <visual name="wheel_down_left">
      <origin rpy="0.00000 -1.57080 0.00000" xyz="-0.00000 0.00000 0.00000"/>
      <material name="black.007"/>
      <geometry>
        <mesh filename="../meshes/dae/Cylinder.002.dae" scale="0.05000 0.05000 0.20000"/>
      </geometry>
    </visual>
  </link>
  <link name="wheel_down_right_link">
    <collision name="wheel_down_right_collision">
      <origin rpy="0.00000 -1.57080 0.00000" xyz="0.00000 0.00000 0.00000"/>
      <geometry>
        <mesh filename="../meshes/dae/Cylinder.003.dae" scale="0.05000 0.05000 0.20000"/>
      </geometry>
    </collision>
    <inertial>
      <inertia ixx="0.28017" ixy="0.00000" ixz="-0.00000" iyy="0.16408" iyz="-0.00000" izz="0.15377"/>
      <origin rpy="0.00000 0.00000 0.00000" xyz="0.00000 0.00000 -0.00000"/>
      <mass value="10.00000"/>
    </inertial>
    <visual name="wheel_down_right">
      <origin rpy="0.00000 -1.57080 0.00000" xyz="0.00000 0.00000 0.00000"/>
      <material name="black.007"/>
      <geometry>
        <mesh filename="../meshes/dae/Cylinder.003.dae" scale="0.05000 0.05000 0.20000"/>
      </geometry>
    </visual>
  </link>
  <link name="wheel_up_left_link">
    <collision name="wheel_up_left_collision">
      <origin rpy="0.00000 -1.57080 0.00000" xyz="-0.00000 0.00000 0.00000"/>
      <geometry>
        <mesh filename="../meshes/dae/Cylinder.001.dae" scale="0.05000 0.05000 0.20000"/>
      </geometry>
    </collision>
    <inertial>
      <inertia ixx="0.28017" ixy="0.00000" ixz="-0.00000" iyy="0.16408" iyz="-0.00000" izz="0.15377"/>
      <origin rpy="0.00000 0.00000 0.00000" xyz="-0.00000 0.00000 0.00000"/>
      <mass value="10.00000"/>
    </inertial>
    <visual name="wheel_up_left">
      <origin rpy="0.00000 -1.57080 0.00000" xyz="-0.00000 0.00000 0.00000"/>
      <material name="black.007"/>
      <geometry>
        <mesh filename="../meshes/dae/Cylinder.001.dae" scale="0.05000 0.05000 0.20000"/>
      </geometry>
    </visual>
  </link>
  <link name="wheel_up_right_link">
    <collision name="wheel_up_right_collision">
      <origin rpy="0.00000 -1.57080 0.00000" xyz="0.00000 0.00000 0.00000"/>
      <geometry>
        <mesh filename="../meshes/dae/Cylinder.dae" scale="0.05000 0.05000 0.20000"/>
      </geometry>
    </collision>
    <inertial>
      <inertia ixx="0.28017" ixy="0.00000" ixz="-0.00000" iyy="0.16408" iyz="-0.00000" izz="0.15377"/>
      <origin rpy="0.00000 0.00000 0.00000" xyz="0.00000 0.00000 -0.00000"/>
      <mass value="10.00000"/>
    </inertial>
    <visual name="wheel_up_right">
      <origin rpy="0.00000 -1.57080 0.00000" xyz="0.00000 0.00000 0.00000"/>
      <material name="black.007"/>
      <geometry>
        <mesh filename="../meshes/dae/Cylinder.dae" scale="0.05000 0.05000 0.20000"/>
      </geometry>
    </visual>
  </link>
  <material name="black.007">
    <color rgba="0.00000 0.00000 0.00000 1.00000"/>
  </material>
  <material name="red.001">
    <color rgba="1.00000 0.00000 0.00000 1.00000"/>
  </material>
  <material name="yellow.001">
    <color rgba="1.00000 1.00000 0.00000 1.00000"/>
  </material>
</robot>